<?xml version="1.0" ?>
<robot name="kr1018" xmlns:xacro="http://www.ros.org/wiki/xacro">
  <xacro:arg name="base_link_name" default="base_link"/>
  <!-- Import Rviz colors -->
  <material name="Black">
    <color rgba="0.0 0.0 0.0 1.0"/>
  </material>
  <material name="Blue">
    <color rgba="0.0 0.0 0.8 1.0"/>
  </material>
  <material name="Green">
    <color rgba="0.0 0.8 0.0 1.0"/>
  </material>
  <material name="Grey">
    <color rgba="0.4 0.4 0.4 1.0"/>
  </material>
  <material name="Orange">
    <color rgba="1.0 0.423529411765 0.0392156862745 1.0"/>
  </material>
  <material name="Brown">
    <color rgba="0.870588235294 0.811764705882 0.764705882353 1.0"/>
  </material>
  <material name="Red">
    <color rgba="0.8 0.0 0.0 1.0"/>
  </material>
  <material name="White">
    <color rgba="1.0 1.0 1.0 1.0"/>
  </material>
  <!--Import the lbr kr macro -->
  <!-- Fix to base_link just for testing -->
  <xacro:macro name="kr_arm" params="base_link_name">
  <link name="${base_link_name}"/>
  <!--kr-->
  <joint name="${base_link_name}_joint" type="fixed">
    <origin rpy="0 0 0" xyz="0 0 0"/>
    <parent link="${base_link_name}"/>
    <child link="kr_link_0"/>
  </joint>
  <link name="kr_link_0">
    <inertial>
      <origin rpy="0 0 0" xyz="-0.1 0 0.07"/>
      <mass value="5"/>
      <inertia ixx="0.05" ixy="0" ixz="0" iyy="0.06" iyz="0" izz="0.03"/>
    </inertial>
    <visual>
      <origin rpy="0 0 0" xyz="0 0 0"/>
      <geometry>
        <mesh filename="package://bunker_description/meshes/kr1018/visual/link_0.stl"/>
      </geometry>
      <material name="Grey"/>
    </visual>
    <collision>
      <origin rpy="0 0 0" xyz="0 0 0"/>
      <geometry>
        <mesh filename="package://bunker_description/meshes/kr1018/collision/link_0.stl"/>
      </geometry>
      <material name="Grey"/>
    </collision>
    <self_collision_checking>
      <origin rpy="0 0 0" xyz="0 0 0"/>
      <geometry>
        <capsule length="0.25" radius="0.15"/>
      </geometry>
    </self_collision_checking>
  </link>
  <joint name="kr_joint_1" type="revolute">
    <parent link="kr_link_0"/>
    <child link="kr_link_1"/>
    <origin rpy="0 0 0" xyz="0.017 0 0.2432"/>
    <axis xyz="0 0 1"/>
    <limit effort="300" lower="-2.96705972839" upper="2.96705972839" velocity="10"/>
    <safety_controller k_position="100" k_velocity="2" soft_lower_limit="-2.93215314335" soft_upper_limit="2.93215314335"/>
    <dynamics damping="0.5"/>
  </joint>
  <link name="kr_link_1">
    <inertial>
      <origin rpy="0 0 0" xyz="0 -0.03 0.12"/>
      <mass value="4"/>
      <inertia ixx="0.1" ixy="0" ixz="0" iyy="0.09" iyz="0" izz="0.02"/>
    </inertial>
    <visual>
      <origin rpy="0 0 0" xyz="0 0 0"/>
      <geometry>
        <mesh filename="package://bunker_description/meshes/kr1018/visual/link_1.stl"/>
      </geometry>
      <material name="Grey"/>
    </visual>
    <collision>
      <origin rpy="0 0 0" xyz="0 0 0"/>
      <geometry>
        <mesh filename="package://bunker_description/meshes/kr1018/collision/link_1.stl"/>
      </geometry>
      <material name="Grey"/>
    </collision>
  </link>
  <joint name="kr_joint_2" type="revolute">
    <parent link="kr_link_1"/>
    <child link="kr_link_2"/>
    <origin rpy="1.57079632679   0 3.14159265359" xyz="0.062 0.0462 0.13"/>
    <axis xyz="0 0 1"/>
    <limit effort="300" lower="-2.09439510239" upper="2.09439510239" velocity="10"/>
    <safety_controller k_position="100" k_velocity="2" soft_lower_limit="-2.05948851735" soft_upper_limit="2.05948851735"/>
    <dynamics damping="0.5"/>
  </joint>
  <link name="kr_link_2">
    <inertial>
      <origin rpy="0 0 0" xyz="0.0003 0.059 0.042"/>
      <mass value="4"/>
      <inertia ixx="0.05" ixy="0" ixz="0" iyy="0.018" iyz="0" izz="0.044"/>
    </inertial>
    <visual>
      <origin rpy="0 0 0" xyz="0 0 0"/>
      <geometry>
        <mesh filename="package://bunker_description/meshes/kr1018/visual/link_2.stl"/>
      </geometry>
      <material name="Grey"/>
    </visual>
    <collision>
      <origin rpy="0 0 0" xyz="0 0 0"/>
      <geometry>
        <mesh filename="package://bunker_description/meshes/kr1018/collision/link_2.stl"/>
      </geometry>
      <material name="Grey"/>
    </collision>
  </link>
  <joint name="kr_joint_3" type="revolute">
    <parent link="kr_link_2"/>
    <child link="kr_link_3"/>
    <origin rpy="1.57079632679 0 3.14159265359" xyz="0.062 0.2908 0.0647"/>
    <axis xyz="0 0 1"/>
    <limit effort="300" lower="-2.96705972839" upper="2.96705972839" velocity="10"/>
    <safety_controller k_position="100" k_velocity="2" soft_lower_limit="-2.93215314335" soft_upper_limit="2.93215314335"/>
    <dynamics damping="0.5"/>
  </joint>
  <link name="kr_link_3">
    <inertial>
      <origin rpy="0 0 0" xyz="0 0.03 0.13"/>
      <mass value="3"/>
      <inertia ixx="0.08" ixy="0" ixz="0" iyy="0.075" iyz="0" izz="0.01"/>
    </inertial>
    <visual>
      <origin rpy="0 0 0" xyz="0 0 0"/>
      <geometry>
        <mesh filename="package://bunker_description/meshes/kr1018/visual/link_3.stl"/>
      </geometry>
      <material name="Grey"/>
    </visual>
    <collision>
      <origin rpy="0 0 0" xyz="0 0 0"/>
      <geometry>
        <mesh filename="package://bunker_description/meshes/kr1018/collision/link_3.stl"/>
      </geometry>
      <material name="Grey"/>
    </collision>
  </link>
  <joint name="kr_joint_4" type="revolute">
    <parent link="kr_link_3"/>
    <child link="kr_link_4"/>
    <origin rpy="1.57079632679 0 0" xyz="0.05 -0.0407 0.2317"/>
    <axis xyz="0 0 1"/>
    <limit effort="300" lower="-2.09439510239" upper="2.09439510239" velocity="10"/>
    <safety_controller k_position="100" k_velocity="2" soft_lower_limit="-2.05948851735" soft_upper_limit="2.05948851735"/>
    <dynamics damping="0.5"/>
  </joint>
  <link name="kr_link_4">
    <inertial>
      <origin rpy="0 0 0" xyz="0 0.067 0.034"/>
      <mass value="2.7"/>
      <inertia ixx="0.03" ixy="0" ixz="0" iyy="0.01" iyz="0" izz="0.029"/>
    </inertial>
    <visual>
      <origin rpy="0 0 0" xyz="0 0 0"/>
      <geometry>
        <mesh filename="package://bunker_description/meshes/kr1018/visual/link_4.stl"/>
      </geometry>
      <material name="Grey"/>
    </visual>
    <collision>
      <origin rpy="0 0 0" xyz="0 0 0"/>
      <geometry>
        <mesh filename="package://bunker_description/meshes/kr1018/collision/link_4.stl"/>
      </geometry>
      <material name="Grey"/>
    </collision>
  </link>
  <joint name="kr_joint_5" type="revolute">
    <parent link="kr_link_4"/>
    <child link="kr_link_5"/>
    <origin rpy="-1.57079632679 3.14159265359 0" xyz="-0.05 0.4195 0.0532"/>
    <axis xyz="0 0 1"/>
    <limit effort="300" lower="-2.96705972839" upper="2.96705972839" velocity="10"/>
    <safety_controller k_position="100" k_velocity="2" soft_lower_limit="-2.93215314335" soft_upper_limit="2.93215314335"/>
    <dynamics damping="0.5"/>
  </joint>
  <link name="kr_link_5">
    <inertial>
      <origin rpy="0 0 0" xyz="0.0001 0.021 0.076"/>
      <mass value="1.7"/>
      <inertia ixx="0.02" ixy="0" ixz="0" iyy="0.018" iyz="0" izz="0.005"/>
    </inertial>
    <visual>
      <origin rpy="0 0 0" xyz="0 0 0"/>
      <geometry>
        <mesh filename="package://bunker_description/meshes/kr1018/visual/link_5.stl"/>
      </geometry>
      <material name="Grey"/>
    </visual>
    <collision>
      <origin rpy="0 0 0" xyz="0 0 0"/>
      <geometry>
        <mesh filename="package://bunker_description/meshes/kr1018/collision/link_5.stl"/>
      </geometry>
      <material name="Grey"/>
    </collision>
  </link>
  <joint name="kr_joint_6" type="revolute">
    <parent link="kr_link_5"/>
    <child link="kr_link_6"/>
    <origin rpy="1.57079632679 0 0" xyz="0 -0.0645 0.0465"/>
    <axis xyz="0 0 1"/>
    <limit effort="300" lower="-2.09439510239" upper="2.09439510239" velocity="10"/>
    <safety_controller k_position="100" k_velocity="2" soft_lower_limit="-2.05948851735" soft_upper_limit="2.05948851735"/>
    <dynamics damping="0.5"/>
  </joint>
  <link name="kr_link_6">
    <inertial>
      <origin rpy="0 0 0" xyz="0 0.0006 0.0004"/>
      <mass value="1.8"/>
      <inertia ixx="0.005" ixy="0" ixz="0" iyy="0.0036" iyz="0" izz="0.0047"/>
    </inertial>
    <visual>
      <origin rpy="0 0 0" xyz="0 0 0"/>
      <geometry>
        <mesh filename="package://bunker_description/meshes/kr1018/visual/link_6.stl"/>
      </geometry>
      <material name="Grey"/>
    </visual>
    <collision>
      <origin rpy="0 0 0" xyz="0 0 0"/>
      <geometry>
        <mesh filename="package://bunker_description/meshes/kr1018/collision/link_6.stl"/>
      </geometry>
      <material name="Grey"/>
    </collision>
  </link>
  <joint name="kr_joint_7" type="revolute">
    <parent link="kr_link_6"/>
    <child link="kr_link_7"/>
    <origin rpy="-1.57079632679 3.14159265359 0" xyz="0 0.05655 0.0465"/>
    <axis xyz="0 0 1"/>
    <limit effort="300" lower="-3.05432619099" upper="3.05432619099" velocity="10"/>
    <safety_controller k_position="100" k_velocity="2" soft_lower_limit="-3.01941960595" soft_upper_limit="3.01941960595"/>
    <dynamics damping="0.5"/>
  </joint>
  <link name="kr_link_7">
    <inertial>
      <origin rpy="0 0 0" xyz="0 0 0.02"/>
      <mass value="0.3"/>
      <inertia ixx="0.001" ixy="0" ixz="0" iyy="0.001" iyz="0" izz="0.001"/>
    </inertial>
    <visual>
      <origin rpy="0 0 0" xyz="0 0 0"/>
      <geometry>
        <mesh filename="package://bunker_description/meshes/kr1018/visual/link_7.stl"/>
      </geometry>
      <material name="Grey"/>
    </visual>
    <collision>
      <origin rpy="0 0 0" xyz="0 0 0"/>
      <geometry>
        <mesh filename="package://bunker_description/meshes/kr1018/collision/link_7.stl"/>
      </geometry>
      <material name="Grey"/>
    </collision>
  </link>
  <joint name="kr_joint_ee" type="fixed">
    <parent link="kr_link_7"/>
    <child link="kr_link_ee"/>
    <origin rpy="0 -1.57079632679 0" xyz="0 0 0.05145"/>
  </joint>
  <link name="kr_link_ee">
    </link>
  <joint name="kr_joint_ee_kuka" type="fixed">
    <parent link="kr_link_7"/>
    <child link="kr_link_ee_kuka"/>
    <origin rpy="3.14159265359 3.14159265359 3.14159265359" xyz="0 0 0.045"/>
    <axis xyz="0 0 1"/>
  </joint>
  <link name="kr_link_ee_kuka">
  </link>
  </xacro:macro>
  <xacro:kr_arm base_link_name="$(arg base_link_name)"/>
  <gazebo>
    <plugin filename="libgazebo_ros_control.so" name="gazebo_ros_control">
      <robotNamespace>/kr</robotNamespace>
    </plugin>
  </gazebo>
  <gazebo reference="kr_link_0">
    <material>Gazebo/Grey</material>
    <mu1>0.2</mu1>
    <mu2>0.2</mu2>
  </gazebo>
  <gazebo reference="kr_link_1">
    <material>Gazebo/Grey</material>
    <mu1>0.2</mu1>
    <mu2>0.2</mu2>
  </gazebo>
  <gazebo reference="kr_link_2">
    <material>Gazebo/Grey</material>
    <mu1>0.2</mu1>
    <mu2>0.2</mu2>
  </gazebo>
  <gazebo reference="kr_link_3">
    <material>Gazebo/Grey</material>
    <mu1>0.2</mu1>
    <mu2>0.2</mu2>
  </gazebo>
  <gazebo reference="kr_link_4">
    <material>Gazebo/Grey</material>
    <mu1>0.2</mu1>
    <mu2>0.2</mu2>
  </gazebo>
  <gazebo reference="kr_link_5">
    <material>Gazebo/Grey</material>
    <mu1>0.2</mu1>
    <mu2>0.2</mu2>
  </gazebo>
  <gazebo reference="kr_link_6">
    <material>Gazebo/Grey</material>
    <mu1>0.2</mu1>
    <mu2>0.2</mu2>
  </gazebo>
  <gazebo reference="kr_link_7">
    <material>Gazebo/Grey</material>
    <mu1>0.2</mu1>
    <mu2>0.2</mu2>
  </gazebo>
  <transmission name="kr_tran_1">
    <robotNamespace>/kr</robotNamespace>
    <type>transmission_interface/SimpleTransmission</type>
    <joint name="kr_joint_1">
      <hardwareInterface>PositionJointInterface</hardwareInterface>
    </joint>
    <actuator name="kr_motor_1">
      <hardwareInterface>PositionJointInterface</hardwareInterface>
      <mechanicalReduction>1</mechanicalReduction>
    </actuator>
  </transmission>
  <transmission name="kr_tran_2">
    <robotNamespace>/kr</robotNamespace>
    <type>transmission_interface/SimpleTransmission</type>
    <joint name="kr_joint_2">
      <hardwareInterface>PositionJointInterface</hardwareInterface>
    </joint>
    <actuator name="kr_motor_2">
      <hardwareInterface>PositionJointInterface</hardwareInterface>
      <mechanicalReduction>1</mechanicalReduction>
    </actuator>
  </transmission>
  <transmission name="kr_tran_3">
    <robotNamespace>/kr</robotNamespace>
    <type>transmission_interface/SimpleTransmission</type>
    <joint name="kr_joint_3">
      <hardwareInterface>PositionJointInterface</hardwareInterface>
    </joint>
    <actuator name="kr_motor_3">
      <hardwareInterface>PositionJointInterface</hardwareInterface>
      <mechanicalReduction>1</mechanicalReduction>
    </actuator>
  </transmission>
  <transmission name="kr_tran_4">
    <robotNamespace>/kr</robotNamespace>
    <type>transmission_interface/SimpleTransmission</type>
    <joint name="kr_joint_4">
      <hardwareInterface>PositionJointInterface</hardwareInterface>
    </joint>
    <actuator name="kr_motor_4">
      <hardwareInterface>PositionJointInterface</hardwareInterface>
      <mechanicalReduction>1</mechanicalReduction>
    </actuator>
  </transmission>
  <transmission name="kr_tran_5">
    <robotNamespace>/kr</robotNamespace>
    <type>transmission_interface/SimpleTransmission</type>
    <joint name="kr_joint_5">
      <hardwareInterface>PositionJointInterface</hardwareInterface>
    </joint>
    <actuator name="kr_motor_5">
      <hardwareInterface>PositionJointInterface</hardwareInterface>
      <mechanicalReduction>1</mechanicalReduction>
    </actuator>
  </transmission>
  <transmission name="kr_tran_6">
    <robotNamespace>/kr</robotNamespace>
    <type>transmission_interface/SimpleTransmission</type>
    <joint name="kr_joint_6">
      <hardwareInterface>PositionJointInterface</hardwareInterface>
    </joint>
    <actuator name="kr_motor_6">
      <hardwareInterface>PositionJointInterface</hardwareInterface>
      <mechanicalReduction>1</mechanicalReduction>
    </actuator>
  </transmission>
  <transmission name="kr_tran_7">
    <robotNamespace>/kr</robotNamespace>
    <type>transmission_interface/SimpleTransmission</type>
    <joint name="kr_joint_7">
      <hardwareInterface>PositionJointInterface</hardwareInterface>
    </joint>
    <actuator name="kr_motor_7">
      <hardwareInterface>PositionJointInterface</hardwareInterface>
      <mechanicalReduction>1</mechanicalReduction>
    </actuator>
  </transmission>
</robot>
